<?xml version="1.0" encoding="utf-8"?>
<!-- This URDF was automatically created by SolidWorks to URDF Exporter! Originally created by Stephen Brawner (brawner@gmail.com) 
     Commit Version: 1.6.0-1-g15f4949  Build Version: 1.6.7594.29634
     For more information, please see http://wiki.ros.org/sw_urdf_exporter -->
<robot
  name="robot_sim">
  <link
    name="base_footprint">
    <inertial>
      <origin
        xyz="0.0052739 -2.8139E-05 0.074999"
        rpy="0 0 0" />
      <mass
        value="1.4696" />
      <inertia
        ixx="0.0011406"
        ixy="1.9447E-07"
        ixz="-1.2749E-06"
        iyy="0.0025151"
        iyz="-8.4742E-07"
        izz="0.0026747" />
    </inertial>
    <visual>
      <origin
        xyz="0 0 0"
        rpy="0 0 0" />
      <geometry>
        <mesh
          filename="package://robot_sim/meshes/base_footprint.STL" />
      </geometry>
      <material
        name="">
        <color
          rgba="1 1 1 1" />
      </material>
    </visual>
    <collision>
      <origin
        xyz="0 0 0"
        rpy="0 0 0" />
      <geometry>
        <mesh
          filename="package://robot_sim/meshes/base_footprint.STL" />
      </geometry>
    </collision>
  </link>
  <joint
    name="wheel_back_right_joint"
    type="fixed">
    <origin
      xyz="-0.09 -0.098854 -0.037"
      rpy="0 0 0" />
    <parent
      link="base_link" />
    <child
      link="wheel_back_right_link" />
    <axis
      xyz="0 0 0" />
  </joint>
  <link
    name="base_link">
    <inertial>
      <origin
        xyz="-0.0048856 -0.0011362 0.0093629"
        rpy="0 0 0" />
      <mass
        value="0.59784" />
      <inertia
        ixx="0.00044776"
        ixy="1.8768E-19"
        ixz="2.7987E-21"
        iyy="0.0015843"
        iyz="-3.1507E-20"
        izz="0.0019808" />
    </inertial>
    <visual>
      <origin
        xyz="0 0 0"
        rpy="0 0 0" />
      <geometry>
        <mesh
          filename="package://robot_sim/meshes/base_link.STL" />
      </geometry>
      <material
        name="">
        <color
          rgba="1 1 1 1" />
      </material>
    </visual>
    <collision>
      <origin
        xyz="0 0 0"
        rpy="0 0 0" />
      <geometry>
        <mesh
          filename="package://robot_sim/meshes/base_link.STL" />
      </geometry>
    </collision>
  </link>
  <joint
    name="base_joint"
    type="fixed">
    <origin
      xyz="0.0067199 0.0011046 0.085"
      rpy="0 0 0" />
    <parent
      link="base_footprint" />
    <child
      link="base_link" />
    <axis
      xyz="0 0 0" />
  </joint>
  <link
    name="wheel_front_left_link">
    <inertial>
      <origin
        xyz="-1.3675E-06 6.2077E-06 4.5411E-06"
        rpy="0 0 0" />
      <mass
        value="0.19171" />
      <inertia
        ixx="0.00013676"
        ixy="9.5175E-09"
        ixz="1.5304E-09"
        iyy="0.00022818"
        iyz="-6.6419E-09"
        izz="0.00013676" />
    </inertial>
    <visual>
      <origin
        xyz="0 0 0"
        rpy="0 0 0" />
      <geometry>
        <mesh
          filename="package://robot_sim/meshes/wheel_front_left_link.STL" />
      </geometry>
      <material
        name="">
        <color
          rgba="0.79216 0.81961 0.93333 1" />
      </material>
    </visual>
    <collision>
      <origin
        xyz="0 0 0"
        rpy="0 0 0" />
      <geometry>
        <mesh
          filename="package://robot_sim/meshes/wheel_front_left_link.STL" />
      </geometry>
    </collision>
  </link>
  <joint
    name="wheel_front_left_joint"
    type="continuous">
    <origin
      xyz="0.075 0.096581 -0.037"
      rpy="3.1416 0 0" />
    <parent
      link="base_link" />
    <child
      link="wheel_front_left_link" />
    <axis
      xyz="0 1 0" />
  </joint>
  <link
    name="wheel_front_right_link">
    <inertial>
      <origin
        xyz="-1.3952E-06 7.9271E-06 -4.5555E-06"
        rpy="0 0 0" />
      <mass
        value="0.19167" />
      <inertia
        ixx="0.00013674"
        ixy="8.5942E-09"
        ixz="1.842E-09"
        iyy="0.00022815"
        iyz="7.22E-09"
        izz="0.00013674" />
    </inertial>
    <visual>
      <origin
        xyz="0 0 0"
        rpy="0 0 0" />
      <geometry>
        <mesh
          filename="package://robot_sim/meshes/wheel_front_right_link.STL" />
      </geometry>
      <material
        name="">
        <color
          rgba="0.79216 0.81961 0.93333 1" />
      </material>
    </visual>
    <collision>
      <origin
        xyz="0 0 0"
        rpy="0 0 0" />
      <geometry>
        <mesh
          filename="package://robot_sim/meshes/wheel_front_right_link.STL" />
      </geometry>
    </collision>
  </link>
  <joint
    name="wheel_front_right_joint"
    type="continuous">
    <origin
      xyz="0.075 -0.098854 -0.037"
      rpy="0 0 0" />
    <parent
      link="base_link" />
    <child
      link="wheel_front_right_link" />
    <axis
      xyz="0 1 0" />
  </joint>
  <link
    name="wheel_back_left_link">
    <inertial>
      <origin
        xyz="1.3952E-06 7.9271E-06 4.5555E-06"
        rpy="0 0 0" />
      <mass
        value="0.19167" />
      <inertia
        ixx="0.00013674"
        ixy="-8.5942E-09"
        ixz="1.842E-09"
        iyy="0.00022815"
        iyz="-7.22E-09"
        izz="0.00013674" />
    </inertial>
    <visual>
      <origin
        xyz="0 0 0"
        rpy="0 0 0" />
      <geometry>
        <mesh
          filename="package://robot_sim/meshes/wheel_back_left_link.STL" />
      </geometry>
      <material
        name="">
        <color
          rgba="0.79216 0.81961 0.93333 1" />
      </material>
    </visual>
    <collision>
      <origin
        xyz="0 0 0"
        rpy="0 0 0" />
      <geometry>
        <mesh
          filename="package://robot_sim/meshes/wheel_back_left_link.STL" />
      </geometry>
    </collision>
  </link>
  <joint
    name="wheel_back_left_joint"
    type="continuous">
    <origin
      xyz="-0.09 0.096581 -0.037"
      rpy="3.1416 0 0" />
    <parent
      link="base_link" />
    <child
      link="wheel_back_left_link" />
    <axis
      xyz="0 1 0" />
  </joint>
  <link
    name="wheel_back_right_link">
    <inertial>
      <origin
        xyz="1.3675E-06 6.2077E-06 -4.5411E-06"
        rpy="0 0 0" />
      <mass
        value="0.19171" />
      <inertia
        ixx="0.00013676"
        ixy="-9.5175E-09"
        ixz="1.5304E-09"
        iyy="0.00022818"
        iyz="6.6418E-09"
        izz="0.00013676" />
    </inertial>
    <visual>
      <origin
        xyz="0 0 0"
        rpy="0 0 0" />
      <geometry>
        <mesh
          filename="package://robot_sim/meshes/wheel_back_right_link.STL" />
      </geometry>
      <material
        name="">
        <color
          rgba="0.79216 0.81961 0.93333 1" />
      </material>
    </visual>
    <collision>
      <origin
        xyz="0 0 0"
        rpy="0 0 0" />
      <geometry>
        <mesh
          filename="package://robot_sim/meshes/wheel_back_right_link.STL" />
      </geometry>
    </collision>
  </link>
  <joint
    name="wheel_back_right_joint"
    type="continuous">
    <origin
      xyz="-0.09 -0.098854 -0.037"
      rpy="0 0 0" />
    <parent
      link="base_link" />
    <child
      link="wheel_back_right_link" />
    <axis
      xyz="0 1 0" />
  </joint>
  <link
    name="camera_link">
    <inertial>
      <origin
        xyz="0.0011843 0.0003548 -0.0033111"
        rpy="0 0 0" />
      <mass
        value="0.081392" />
      <inertia
        ixx="0.00013785"
        ixy="2.1587E-07"
        ixz="-1.3621E-06"
        iyy="1.1529E-05"
        iyz="-8.2079E-07"
        izz="0.00013308" />
    </inertial>
    <visual>
      <origin
        xyz="0 0 0"
        rpy="0 0 0" />
      <geometry>
        <mesh
          filename="package://robot_sim/meshes/camera_link.STL" />
      </geometry>
      <material
        name="">
        <color
          rgba="1 1 1 1" />
      </material>
    </visual>
    <collision>
      <origin
        xyz="0 0 0"
        rpy="0 0 0" />
      <geometry>
        <mesh
          filename="package://robot_sim/meshes/camera_link.STL" />
      </geometry>
    </collision>
  </link>
  <joint
    name="camera_joint"
    type="fixed">
    <origin
      xyz="0.08163 -0.0012919 0.08"
      rpy="0 0 0" />
    <parent
      link="base_link" />
    <child
      link="camera_link" />
    <axis
      xyz="0 0 0" />
  </joint>
  <link
    name="lidar_link">
    <inertial>
      <origin
        xyz="0.0099114 0.0021626 -0.0089204"
        rpy="0 0 0" />
      <mass
        value="0.019617" />
      <inertia
        ixx="7.6914E-06"
        ixy="-1.9553E-08"
        ixz="8.717E-08"
        iyy="6.4932E-06"
        iyz="-2.6626E-08"
        izz="1.3458E-05" />
    </inertial>
    <visual>
      <origin
        xyz="0 0 0"
        rpy="0 0 0" />
      <geometry>
        <mesh
          filename="package://robot_sim/meshes/lidar_link.STL" />
      </geometry>
      <material
        name="">
        <color
          rgba="1 1 1 1" />
      </material>
    </visual>
    <collision>
      <origin
        xyz="0 0 0"
        rpy="0 0 0" />
      <geometry>
        <mesh
          filename="package://robot_sim/meshes/lidar_link.STL" />
      </geometry>
    </collision>
  </link>
  <joint
    name="lidar_joint"
    type="fixed">
    <origin
      xyz="-0.018284 -0.003868 0.11"
      rpy="0 0 0" />
    <parent
      link="base_link" />
    <child
      link="lidar_link" />
    <axis
      xyz="0 0 0" />
  </joint>
</robot>